[2023-11-26T05:59:48.329+0000] {logging_mixin.py:154} INFO - Changing /opt/***/logs/dag_id=outcomes_dag/run_id=manual__2023-11-26T05:59:44.359623+00:00/task_id=trasform permission to 509
[2023-11-26T05:59:48.364+0000] {logging_mixin.py:154} INFO - Changing /opt/***/logs/dag_id=outcomes_dag/run_id=manual__2023-11-26T05:59:44.359623+00:00/task_id=trasform permission to 509
[2023-11-26T05:59:48.399+0000] {taskinstance.py:1159} INFO - Dependencies all met for dep_context=non-requeueable deps ti=<TaskInstance: outcomes_dag.trasform manual__2023-11-26T05:59:44.359623+00:00 [queued]>
[2023-11-26T05:59:48.409+0000] {taskinstance.py:1159} INFO - Dependencies all met for dep_context=requeueable deps ti=<TaskInstance: outcomes_dag.trasform manual__2023-11-26T05:59:44.359623+00:00 [queued]>
[2023-11-26T05:59:48.410+0000] {taskinstance.py:1361} INFO - Starting attempt 1 of 1
[2023-11-26T05:59:48.427+0000] {taskinstance.py:1382} INFO - Executing <Task(PythonOperator): trasform> on 2023-11-26 05:59:44.359623+00:00
[2023-11-26T05:59:48.432+0000] {standard_task_runner.py:57} INFO - Started process 1319 to run task
[2023-11-26T05:59:48.436+0000] {standard_task_runner.py:84} INFO - Running: ['***', 'tasks', 'run', 'outcomes_dag', 'trasform', 'manual__2023-11-26T05:59:44.359623+00:00', '--job-id', '74', '--raw', '--subdir', 'DAGS_FOLDER/outcomes_dag.py', '--cfg-path', '/tmp/tmp71g5gr3h']
[2023-11-26T05:59:48.440+0000] {standard_task_runner.py:85} INFO - Job 74: Subtask trasform
[2023-11-26T05:59:48.484+0000] {logging_mixin.py:154} INFO - Changing /opt/***/logs/dag_id=outcomes_dag/run_id=manual__2023-11-26T05:59:44.359623+00:00/task_id=trasform permission to 509
[2023-11-26T05:59:48.487+0000] {task_command.py:416} INFO - Running <TaskInstance: outcomes_dag.trasform manual__2023-11-26T05:59:44.359623+00:00 [running]> on host 50f4a498a395
[2023-11-26T05:59:48.742+0000] {taskinstance.py:1662} INFO - Exporting env vars: AIRFLOW_CTX_DAG_OWNER='***' AIRFLOW_CTX_DAG_ID='outcomes_dag' AIRFLOW_CTX_TASK_ID='trasform' AIRFLOW_CTX_EXECUTION_DATE='2023-11-26T05:59:44.359623+00:00' AIRFLOW_CTX_TRY_NUMBER='1' AIRFLOW_CTX_DAG_RUN_ID='manual__2023-11-26T05:59:44.359623+00:00'
[2023-11-26T05:59:48.757+0000] {taskinstance.py:1937} ERROR - Task failed with exception
Traceback (most recent call last):
  File "/home/airflow/.local/lib/python3.8/site-packages/pandas/core/indexes/base.py", line 3653, in get_loc
    return self._engine.get_loc(casted_key)
  File "pandas/_libs/index.pyx", line 147, in pandas._libs.index.IndexEngine.get_loc
  File "pandas/_libs/index.pyx", line 176, in pandas._libs.index.IndexEngine.get_loc
  File "pandas/_libs/hashtable_class_helper.pxi", line 7080, in pandas._libs.hashtable.PyObjectHashTable.get_item
  File "pandas/_libs/hashtable_class_helper.pxi", line 7088, in pandas._libs.hashtable.PyObjectHashTable.get_item
KeyError: 'Name'

The above exception was the direct cause of the following exception:

Traceback (most recent call last):
  File "/home/airflow/.local/lib/python3.8/site-packages/airflow/operators/python.py", line 192, in execute
    return_value = self.execute_callable()
  File "/home/airflow/.local/lib/python3.8/site-packages/airflow/operators/python.py", line 209, in execute_callable
    return self.python_callable(*self.op_args, **self.op_kwargs)
  File "/opt/airflow/dags/etl_scripts/transform.py", line 22, in transform_data
    new_data = prep_data(new_data)
  File "/opt/airflow/dags/etl_scripts/transform.py", line 41, in prep_data
    data['name'] = data['Name'].str.replace("*", "", regex=False)
  File "/home/airflow/.local/lib/python3.8/site-packages/pandas/core/frame.py", line 3761, in __getitem__
    indexer = self.columns.get_loc(key)
  File "/home/airflow/.local/lib/python3.8/site-packages/pandas/core/indexes/base.py", line 3655, in get_loc
    raise KeyError(key) from err
KeyError: 'Name'
[2023-11-26T05:59:48.780+0000] {taskinstance.py:1400} INFO - Marking task as FAILED. dag_id=outcomes_dag, task_id=trasform, execution_date=20231126T055944, start_date=20231126T055948, end_date=20231126T055948
[2023-11-26T05:59:48.792+0000] {standard_task_runner.py:104} ERROR - Failed to execute job 74 for task trasform ('Name'; 1319)
[2023-11-26T05:59:48.810+0000] {local_task_job_runner.py:228} INFO - Task exited with return code 1
[2023-11-26T05:59:48.832+0000] {taskinstance.py:2778} INFO - 0 downstream tasks scheduled from follow-on schedule check
